Workbook

Sheet Data availabiliy and weather  
A1: Date | B1: Year | C1: Day of year | D1: Day of week | E1: IOP and Radiosoundings | F1: Number of DWLs operational (max = 6) | G1: Data availability PAROIS DWL | H1: Data availability PACHEM DWL | I1: Data availability PAJUSS DWL | J1: Data availability PALUPD DWL | K1: Data availability PAARBO DWL | L1: Data availability PASIRT DWL | M1: Mean wind direction (300 m) from all running DWLs | N1: Mean wind direction category (300 m) from DWLs | O1: Mean vector wind speed (300m) from all running DWLs | P1: Solar radiation (clear, few, broken, overcast - in Paris area based on daytime conditions) | Q1: Precipitation (mm day-1) MF Montsouris Weather Station | R1: Mean air temperature (°C) at Paris Montsouris | S1: Min air temperature (°C) at Paris Montsouris | T1: Max air temperature (°C) at Paris Montsouris | U1: mean wind direction (°) from Eiffel tower at 330 m agl | V1: Mean wind direction category from Eiffel tower at 330 m agl | W1: Fraction of N wind from Eiffel tower at 330 m agl | X1: Fraction of NE wind from Eiffel tower at 330 m agl | Y1: Fraction of E wind from Eiffel tower at 330 m agl | Z1: Fraction of SE wind from Eiffel tower at 330 m agl | AA1: Fraction of S wind from Eiffel tower at 330 m agl | AB1: Fraction of SW wind from Eiffel tower at 330 m agl | AC1: Fraction of W wind from Eiffel tower at 330 m agl | AD1: Fraction of NW wind from Eiffel tower at 330 m agl | AE1: Mean scalar wind speed (m s^-1) from Eiffel tower at 330 m agl | AF1: Mean vector wind speed (m s^-1) from Eiffel tower at 330 m agl | AG1: Maximum wind speed (m s^-1) from Eiffel tower at 330 m agl | AH1: ID of "Grosswetterlage" (Hess and Brezowsky) | AI1: Synotic conditions Meridional (m), zonal (z) or mixed | AJ1: Anticyclonic (A), cyclonic (C), or mixed (M) | AK1: Description of "Grosswetterlage" (Hess and Brezowsky) | AL1: sunrise (UTC) | AM1: solar noon (UTC) | AN1: sunset (UTC)
A2: 44722 | B2: 2022 | C2: 165 | D2: =WEEKDAY(A2) -> 6 | F2: =IF(G2 > 0.5,1,0)+IF(H2 > 0.5,1,0)+IF(I2 > 0.5,1,0)+IF(J2 > 0.5,1,0)+IF(K2 > 0.5,1,0)+IF(L2 > 0.5,1,0) -> 2 | G2: 0 | H2: 0 | I2: 1 | J2: 0 | K2: 0 | L2: 1 | M2: 237.592 | N2: =IF(AND(M2 > 22.5,M2<=67.6),"NE",IF(AND(M2 > 67.5,M2<=112.5),"E",IF(AND(M2 > 112.5,M2<=157.5),"SE",IF(AND(M2 > 157.5,M2<=202.5),"S",IF(AND(M2 > 202.5,M2<=247.5),"SW",IF(AND(M2 > 247.5,M2<=292.5),"W",IF(AND(M2 > 292.5,M2<=337.5),"NW",IF(AND(M2 > 22.5,M2<=360),"N","N")))))))) -> SW | O2: 4.8 | P2: Broken | Q2: 0 | R2: 19.56 | S2: 14.3 | T2: 23.6 | U2: 231.16 | V2: SW | W2: 0 | X2: 0 | Y2: 0 | Z2: 0 | AA2: 0.12 | AB2: 0.54 | AC2: 0.33 | AD2: 0 | AE2: 3.68 | AF2: 3.35 | AG2: 7.6 | AH2: BM | AI2: =VLOOKUP(AH2,'Hess and Brezowsky'!$B$2:$G$31,2,FALSE) -> Mixed | AJ2: =VLOOKUP(AH2,'Hess and Brezowsky'!$B$2:$G$31,3,FALSE) -> A | AK2: =VLOOKUP(AH2,'Hess and Brezowsky'!$B$2:$G$31,4,FALSE) -> Zonal Ridge across Central Europe | AL2: 0.15886574 | AM2: 0.49402778 | AN2: 0.82917824
A3: 44723 | B3: 2022 | C3: 165 | D3: =WEEKDAY(A3) -> 7 | F3: =IF(G3 > 0.5,1,0)+IF(H3 > 0.5,1,0)+IF(I3 > 0.5,1,0)+IF(J3 > 0.5,1,0)+IF(K3 > 0.5,1,0)+IF(L3 > 0.5,1,0) -> 2 | G3: 0 | H3: 0 | I3: 1 | J3: 0 | K3: 0 | L3: 1 | M3: 334.004 | N3: =IF(AND(M3 > 22.5,M3<=67.6),"NE",IF(AND(M3 > 67.5,M3<=112.5),"E",IF(AND(M3 > 112.5,M3<=157.5),"SE",IF(AND(M3 > 157.5,M3<=202.5),"S",IF(AND(M3 > 202.5,M3<=247.5),"SW",IF(AND(M3 > 247.5,M3<=292.5),"W",IF(AND(M3 > 292.5,M3<=337.5),"NW",IF(AND(M3 > 22.5,M3<=360),"N","N")))))))) -> NW | O3: 3.9 | P3: Broken | Q3: 0 | R3: 20.87 | S3: 16 | T3: 26.3 | U3: 322.49 | V3: NW | W3: 0.42 | X3: 0 | Y3: 0 | Z3: 0 | AA3: 0 | AB3: 0 | AC3: 0.38 | AD3: 0.21 | AE3: 4 | AF3: 3.22 | AG3: 8.7 | AH3: BM | AI3: =VLOOKUP(AH3,'Hess and Brezowsky'!$B$2:$G$31,2,FALSE) -> Mixed | AJ3: =VLOOKUP(AH3,'Hess and Brezowsky'!$B$2:$G$31,3,FALSE) -> A | AK3: =VLOOKUP(AH3,'Hess and Brezowsky'!$B$2:$G$31,4,FALSE) -> Zonal Ridge across Central Europe | AL3: 0.15866898 | AM3: 0.49415509 | AN3: 0.8296412
A4: 44724 | B4: 2022 | C4: 165 | D4: =WEEKDAY(A4) -> 1 | F4: =IF(G4 > 0.5,1,0)+IF(H4 > 0.5,1,0)+IF(I4 > 0.5,1,0)+IF(J4 > 0.5,1,0)+IF(K4 > 0.5,1,0)+IF(L4 > 0.5,1,0) -> 2 | G4: 0 | H4: 0 | I4: 1 | J4: 0 | K4: 0 | L4: 1 | M4: 343.463 | N4: =IF(AND(M4 > 22.5,M4<=67.6),"NE",IF(AND(M4 > 67.5,M4<=112.5),"E",IF(AND(M4 > 112.5,M4<=157.5),"SE",IF(AND(M4 > 157.5,M4<=202.5),"S",IF(AND(M4 > 202.5,M4<=247.5),"SW",IF(AND(M4 > 247.5,M4<=292.5),"W",IF(AND(M4 > 292.5,M4<=337.5),"NW",IF(AND(M4 > 22.5,M4<=360),"N","N")))))))) -> N | O4: 5.4 | P4: Broken | Q4: 0 | R4: 19.15 | S4: 14.4 | T4: 24.6 | U4: 329.32 | V4: NW | W4: 0.38 | X4: 0 | Y4: 0 | Z4: 0 | AA4: 0 | AB4: 0 | AC4: 0 | AD4: 0.62 | AE4: 5.87 | AF4: 5.6 | AG4: 9.8 | AH4: BM | AI4: =VLOOKUP(AH4,'Hess and Brezowsky'!$B$2:$G$31,2,FALSE) -> Mixed | AJ4: =VLOOKUP(AH4,'Hess and Brezowsky'!$B$2:$G$31,3,FALSE) -> A | AK4: =VLOOKUP(AH4,'Hess and Brezowsky'!$B$2:$G$31,4,FALSE) -> Zonal Ridge across Central Europe | AL4: 0.15850694 | AM4: 0.49429398 | AN4: 0.83006944
A5: 44725 | B5: 2022 | C5: 165 | D5: =WEEKDAY(A5) -> 2 | F5: =IF(G5 > 0.5,1,0)+IF(H5 > 0.5,1,0)+IF(I5 > 0.5,1,0)+IF(J5 > 0.5,1,0)+IF(K5 > 0.5,1,0)+IF(L5 > 0.5,1,0) -> 2 | G5: 0 | H5: 0 | I5: 0.95 | J5: 0 | K5: 0 | L5: 1 | M5: 10.014 | N5: =IF(AND(M5 > 22.5,M5<=67.6),"NE",IF(AND(M5 > 67.5,M5<=112.5),"E",IF(AND(M5 > 112.5,M5<=157.5),"SE",IF(AND(M5 > 157.5,M5<=202.5),"S",IF(AND(M5 > 202.5,M5<=247.5),"SW",IF(AND(M5 > 247.5,M5<=292.5),"W",IF(AND(M5 > 292.5,M5<=337.5),"NW",IF(AND(M5 > 22.5,M5<=360),"N","N")))))))) -> N | O5: 4.8 | P5: Few | Q5: 0 | R5: 18.47 | S5: 12.9 | T5: 23.9 | U5: 1.74 | V5: N | W5: 0.46 | X5: 0.21 | Y5: 0.08 | Z5: 0 | AA5: 0 | AB5: 0 | AC5: 0 | AD5: 0.25 | AE5: 5.49 | AF5: 4.18 | AG5: 9.8 | AH5: BM | AI5: =VLOOKUP(AH5,'Hess and Brezowsky'!$B$2:$G$31,2,FALSE) -> Mixed | AJ5: =VLOOKUP(AH5,'Hess and Brezowsky'!$B$2:$G$31,3,FALSE) -> A | AK5: =VLOOKUP(AH5,'Hess and Brezowsky'!$B$2:$G$31,4,FALSE) -> Zonal Ridge across Central Europe | AL5: 0.15837963 | AM5: 0.4944213 | AN5: 0.83047454
A6: 44726 | B6: 2022 | C6: 165 | D6: =WEEKDAY(A6) -> 3 | F6: =IF(G6 > 0.5,1,0)+IF(H6 > 0.5,1,0)+IF(I6 > 0.5,1,0)+IF(J6 > 0.5,1,0)+IF(K6 > 0.5,1,0)+IF(L6 > 0.5,1,0) -> 3 | G6: 0.58 | H6: 0 | I6: 1 | J6: 0 | K6: 0 | L6: 1 | M6: 77.316 | N6: =IF(AND(M6 > 22.5,M6<=67.6),"NE",IF(AND(M6 > 67.5,M6<=112.5),"E",IF(AND(M6 > 112.5,M6<=157.5),"SE",IF(AND(M6 > 157.5,M6<=202.5),"S",IF(AND(M6 > 202.5,M6<=247.5),"SW",IF(AND(M6 > 247.5,M6<=292.5),"W",IF(AND(M6 > 292.5,M6<=337.5),"NW",IF(AND(M6 > 22.5,M6<=360),"N","N")))))))) -> E | O6: 5.5 | P6: Few | Q6: 0 | R6: 21.26 | S6: 13.9 | T6: 27.4 | U6: 82.5 | V6: E | W6: 0 | X6: 0.08 | Y6: 0.92 | Z6: 0 | AA6: 0 | AB6: 0 | AC6: 0 | AD6: 0 | AE6: 5.65 | AF6: 5.53 | AG6: 10 | AH6: HM | AI6: =VLOOKUP(AH6,'Hess and Brezowsky'!$B$2:$G$31,2,FALSE) -> Mixed | AJ6: =VLOOKUP(AH6,'Hess and Brezowsky'!$B$2:$G$31,3,FALSE) -> A | AK6: =VLOOKUP(AH6,'Hess and Brezowsky'!$B$2:$G$31,4,FALSE) -> High over Central Europe | AL6: 0.15827546 | AM6: 0.49456019 | AN6: 0.83084491
A7: 44727 | B7: 2022 | C7: 166 | D7: =WEEKDAY(A7) -> 4 | F7: =IF(G7 > 0.5,1,0)+IF(H7 > 0.5,1,0)+IF(I7 > 0.5,1,0)+IF(J7 > 0.5,1,0)+IF(K7 > 0.5,1,0)+IF(L7 > 0.5,1,0) -> 3 | G7: 0.95 | H7: 0 | I7: 1 | J7: 0 | K7: 0 | L7: 1 | M7: 33.088 | N7: =IF(AND(M7 > 22.5,M7<=67.6),"NE",IF(AND(M7 > 67.5,M7<=112.5),"E",IF(AND(M7 > 112.5,M7<=157.5),"SE",IF(AND(M7 > 157.5,M7<=202.5),"S",IF(AND(M7 > 202.5,M7<=247.5),"SW",IF(AND(M7 > 247.5,M7<=292.5),"W",IF(AND(M7 > 292.5,M7<=337.5),"NW",IF(AND(M7 > 22.5,M7<=360),"N","N")))))))) -> NE | O7: 6 | P7: Few | Q7: 0 | R7: 24.26 | S7: 16.6 | T7: 30.9 | U7: 37.47 | V7: NE | W7: 0.38 | X7: 0.21 | Y7: 0.29 | Z7: 0 | AA7: 0 | AB7: 0 | AC7: 0 | AD7: 0.12 | AE7: 5.51 | AF7: 4.31 | AG7: 9.5 | AH7: HM | AI7: =VLOOKUP(AH7,'Hess and Brezowsky'!$B$2:$G$31,2,FALSE) -> Mixed | AJ7: =VLOOKUP(AH7,'Hess and Brezowsky'!$B$2:$G$31,3,FALSE) -> A | AK7: =VLOOKUP(AH7,'Hess and Brezowsky'!$B$2:$G$31,4,FALSE) -> High over Central Europe | AL7: 0.15820602 | AM7: 0.49469907 | AN7: 0.83119213
A8: 44728 | B8: 2022 | C8: 167 | D8: =WEEKDAY(A8) -> 5 | F8: =IF(G8 > 0.5,1,0)+IF(H8 > 0.5,1,0)+IF(I8 > 0.5,1,0)+IF(J8 > 0.5,1,0)+IF(K8 > 0.5,1,0)+IF(L8 > 0.5,1,0) -> 3 | G8: 1 | H8: 0 | I8: 1 | J8: 0 | K8: 0 | L8: 1 | M8: 35.653 | N8: =IF(AND(M8 > 22.5,M8<=67.6),"NE",IF(AND(M8 > 67.5,M8<=112.5),"E",IF(AND(M8 > 112.5,M8<=157.5),"SE",IF(AND(M8 > 157.5,M8<=202.5),"S",IF(AND(M8 > 202.5,M8<=247.5),"SW",IF(AND(M8 > 247.5,M8<=292.5),"W",IF(AND(M8 > 292.5,M8<=337.5),"NW",IF(AND(M8 > 22.5,M8<=360),"N","N")))))))) -> NE | O8: 4.6 | P8: Few | Q8: 0 | R8: 24.32 | S8: 18.2 | T8: 30.3 | U8: 37.78 | V8: NE | W8: 0.21 | X8: 0.75 | Y8: 0.04 | Z8: 0 | AA8: 0 | AB8: 0 | AC8: 0 | AD8: 0 | AE8: 4.05 | AF8: 3.81 | AG8: 7.5 | AH8: HM | AI8: =VLOOKUP(AH8,'Hess and Brezowsky'!$B$2:$G$31,2,FALSE) -> Mixed | AJ8: =VLOOKUP(AH8,'Hess and Brezowsky'!$B$2:$G$31,3,FALSE) -> A | AK8: =VLOOKUP(AH8,'Hess and Brezowsky'!$B$2:$G$31,4,FALSE) -> High over Central Europe | AL8: 0.1581713 | AM8: 0.49483796 | AN8: 0.83150463
A9: 44729 | B9: 2022 | C9: 168 | D9: =WEEKDAY(A9) -> 6 | F9: =IF(G9 > 0.5,1,0)+IF(H9 > 0.5,1,0)+IF(I9 > 0.5,1,0)+IF(J9 > 0.5,1,0)+IF(K9 > 0.5,1,0)+IF(L9 > 0.5,1,0) -> 3 | G9: 0.79 | H9: 0 | I9: 1 | J9: 0 | K9: 0 | L9: 1 | M9: 150.587 | N9: =IF(AND(M9 > 22.5,M9<=67.6),"NE",IF(AND(M9 > 67.5,M9<=112.5),"E",IF(AND(M9 > 112.5,M9<=157.5),"SE",IF(AND(M9 > 157.5,M9<=202.5),"S",IF(AND(M9 > 202.5,M9<=247.5),"SW",IF(AND(M9 > 247.5,M9<=292.5),"W",IF(AND(M9 > 292.5,M9<=337.5),"NW",IF(AND(M9 > 22.5,M9<=360),"N","N")))))))) -> SE | O9: 4.5 | P9: Clear | Q9: 0 | R9: 27.16 | S9: 19.1 | T9: 34.9 | U9: 148.61 | V9: SE | W9: 0 | X9: 0 | Y9: 0.12 | Z9: 0.21 | AA9: 0.46 | AB9: 0.21 | AC9: 0 | AD9: 0 | AE9: 3.92 | AF9: 3.05 | AG9: 8.4 | AH9: HM | AI9: =VLOOKUP(AH9,'Hess and Brezowsky'!$B$2:$G$31,2,FALSE) -> Mixed | AJ9: =VLOOKUP(AH9,'Hess and Brezowsky'!$B$2:$G$31,3,FALSE) -> A | AK9: =VLOOKUP(AH9,'Hess and Brezowsky'!$B$2:$G$31,4,FALSE) -> High over Central Europe | AL9: 0.1581713 | AM9: 0.49497685 | AN9: 0.83179398
A10: 44730 | B10: 2022 | C10: 169 | D10: =WEEKDAY(A10) -> 7 | F10: =IF(G10 > 0.5,1,0)+IF(H10 > 0.5,1,0)+IF(I10 > 0.5,1,0)+IF(J10 > 0.5,1,0)+IF(K10 > 0.5,1,0)+IF(L10 > 0.5,1,0) -> 3 | G10: 0.66 | H10: 0 | I10: 1 | J10: 0 | K10: 0 | L10: 0.91 | M10: 162.855 | N10: =IF(AND(M10 > 22.5,M10<=67.6),"NE",IF(AND(M10 > 67.5,M10<=112.5),"E",IF(AND(M10 > 112.5,M10<=157.5),"SE",IF(AND(M10 > 157.5,M10<=202.5),"S",IF(AND(M10 > 202.5,M10<=247.5),"SW",IF(AND(M10 > 247.5,M10<=292.5),"W",IF(AND(M10 > 292.5,M10<=337.5),"NW",IF(AND(M10 > 22.5,M10<=360),"N","N")))))))) -> S | O10: 6.3 | P10: Clear | Q10: 0 | R10: 29.72 | S10: 21.2 | T10: 36.7 | U10: 164.22 | V10: S | W10: 0 | X10: 0 | Y10: 0 | Z10: 0.46 | AA10: 0.5 | AB10: 0.04 | AC10: 0 | AD10: 0 | AE10: 6.28 | AF10: 5.68 | AG10: 15 | AH10: Ü | AI10: =VLOOKUP(AH10,'Hess and Brezowsky'!$B$2:$G$31,2,FALSE) -> Undefined | AJ10: =VLOOKUP(AH10,'Hess and Brezowsky'!$B$2:$G$31,3,FALSE) -> M | AK10: =VLOOKUP(AH10,'Hess and Brezowsky'!$B$2:$G$31,4,FALSE) -> Transistion / Undefined | AL10: 0.15819444 | AM10: 0.49511574 | AN10: 0.83204861
A11: 44731 | B11: 2022 | C11: 170 | D11: =WEEKDAY(A11) -> 1 | F11: =IF(G11 > 0.5,1,0)+IF(H11 > 0.5,1,0)+IF(I11 > 0.5,1,0)+IF(J11 > 0.5,1,0)+IF(K11 > 0.5,1,0)+IF(L11 > 0.5,1,0) -> 3 | G11: 1 | H11: 0 | I11: 1 | J11: 0 | K11: 0 | L11: 1 | M11: 15.896 | N11: =IF(AND(M11 > 22.5,M11<=67.6),"NE",IF(AND(M11 > 67.5,M11<=112.5),"E",IF(AND(M11 > 112.5,M11<=157.5),"SE",IF(AND(M11 > 157.5,M11<=202.5),"S",IF(AND(M11 > 202.5,M11<=247.5),"SW",IF(AND(M11 > 247.5,M11<=292.5),"W",IF(AND(M11 > 292.5,M11<=337.5),"NW",IF(AND(M11 > 22.5,M11<=360),"N","N")))))))) -> N | O11: 7.4 | P11: Broken | Q11: 5.6 | R11: 19.78 | S11: 15.4 | T11: 26.7 | U11: 13.97 | V11: N | W11: 0.42 | X11: 0.46 | Y11: 0 | Z11: 0 | AA11: 0 | AB11: 0 | AC11: 0 | AD11: 0.12 | AE11: 6.98 | AF11: 6.36 | AG11: 14.6 | AH11: HB | AI11: =VLOOKUP(AH11,'Hess and Brezowsky'!$B$2:$G$31,2,FALSE) -> Meridional | AJ11: =VLOOKUP(AH11,'Hess and Brezowsky'!$B$2:$G$31,3,FALSE) -> A | AK11: =VLOOKUP(AH11,'Hess and Brezowsky'!$B$2:$G$31,4,FALSE) -> High over the British Isles | AL11: 0.15825231 | AM11: 0.4952662 | AN11: 0.83228009
A12: 44732 | B12: 2022 | C12: 171 | D12: =WEEKDAY(A12) -> 2 | F12: =IF(G12 > 0.5,1,0)+IF(H12 > 0.5,1,0)+IF(I12 > 0.5,1,0)+IF(J12 > 0.5,1,0)+IF(K12 > 0.5,1,0)+IF(L12 > 0.5,1,0) -> 3 | G12: 1 | H12: 0 | I12: 1 | J12: 0 | K12: 0 | L12: 1 | M12: 46.593 | N12: =IF(AND(M12 > 22.5,M12<=67.6),"NE",IF(AND(M12 > 67.5,M12<=112.5),"E",IF(AND(M12 > 112.5,M12<=157.5),"SE",IF(AND(M12 > 157.5,M12<=202.5),"S",IF(AND(M12 > 202.5,M12<=247.5),"SW",IF(AND(M12 > 247.5,M12<=292.5),"W",IF(AND(M12 > 292.5,M12<=337.5),"NW",IF(AND(M12 > 22.5,M12<=360),"N","N")))))))) -> NE | O12: 6.4 | P12: Broken | Q12: 8.3 | R12: 18.39 | S12: 14.7 | T12: 23 | U12: 43.71 | V12: NE | W12: 0.08 | X12: 0.75 | Y12: 0.12 | Z12: 0 | AA12: 0 | AB12: 0 | AC12: 0 | AD12: 0.04 | AE12: 6.02 | AF12: 5.41 | AG12: 11.7 | AH12: HB | AI12: =VLOOKUP(AH12,'Hess and Brezowsky'!$B$2:$G$31,2,FALSE) -> Meridional | AJ12: =VLOOKUP(AH12,'Hess and Brezowsky'!$B$2:$G$31,3,FALSE) -> A | AK12: =VLOOKUP(AH12,'Hess and Brezowsky'!$B$2:$G$31,4,FALSE) -> High over the British Isles | AL12: 0.15833333 | AM12: 0.49540509 | AN12: 0.83247685
A13: 44733 | B13: 2022 | C13: 172 | D13: =WEEKDAY(A13) -> 3 | F13: =IF(G13 > 0.5,1,0)+IF(H13 > 0.5,1,0)+IF(I13 > 0.5,1,0)+IF(J13 > 0.5,1,0)+IF(K13 > 0.5,1,0)+IF(L13 > 0.5,1,0) -> 3 | G13: 1 | H13: 0 | I13: 1 | J13: 0 | K13: 0 | L13: 1 | M13: 56.234 | N13: =IF(AND(M13 > 22.5,M13<=67.6),"NE",IF(AND(M13 > 67.5,M13<=112.5),"E",IF(AND(M13 > 112.5,M13<=157.5),"SE",IF(AND(M13 > 157.5,M13<=202.5),"S",IF(AND(M13 > 202.5,M13<=247.5),"SW",IF(AND(M13 > 247.5,M13<=292.5),"W",IF(AND(M13 > 292.5,M13<=337.5),"NW",IF(AND(M13 > 22.5,M13<=360),"N","N")))))))) -> NE | O13: 5.3 | P13: Broken | Q13: 0.8 | R13: 21.21 | S13: 14.9 | T13: 27.3 | U13: 56.75 | V13: NE | W13: 0.17 | X13: 0.54 | Y13: 0.21 | Z13: 0.08 | AA13: 0 | AB13: 0 | AC13: 0 | AD13: 0 | AE13: 4.9 | AF13: 4.53 | AG13: 9.8 | AH13: HB | AI13: =VLOOKUP(AH13,'Hess and Brezowsky'!$B$2:$G$31,2,FALSE) -> Meridional | AJ13: =VLOOKUP(AH13,'Hess and Brezowsky'!$B$2:$G$31,3,FALSE) -> A | AK13: =VLOOKUP(AH13,'Hess and Brezowsky'!$B$2:$G$31,4,FALSE) -> High over the British Isles | AL13: 0.15844907 | AM13: 0.49554398 | AN13: 0.83263889
... A181: 44901 | B181: 2022 | C181: 340 | D181: =WEEKDAY(A181) -> 3 | F181: =IF(G181 > 0.5,1,0)+IF(H181 > 0.5,1,0)+IF(I181 > 0.5,1,0)+IF(J181 > 0.5,1,0)+IF(K181 > 0.5,1,0)+IF(L181 > 0.5,1,0) -> 3 | G181: 1 | H181: 0 | I181: 0.91 | J181: 0 | K181: 0 | L181: 1 | M181: 25.836 | N181: =IF(AND(M181 > 22.5,M181<=67.6),"NE",IF(AND(M181 > 67.5,M181<=112.5),"E",IF(AND(M181 > 112.5,M181<=157.5),"SE",IF(AND(M181 > 157.5,M181<=202.5),"S",IF(AND(M181 > 202.5,M181<=247.5),"SW",IF(AND(M181 > 247.5,M181<=292.5),"W",IF(AND(M181 > 292.5,M181<=337.5),"NW",IF(AND(M181 > 22.5,M181<=360),"N","N")))))))) -> NE | O181: 3.9 | P181: Overcast | Q181: 0 | R181: 3.84 | S181: 2.5 | T181: 5.5 | U181: 26.74 | V181: NE | W181: 0.17 | X181: 0.75 | Y181: 0 | Z181: 0 | AA181: 0 | AB181: 0 | AC181: 0 | AD181: 0.08 | AE181: 3.91 | AF181: 3.75 | AG181: 7.7 | AH181: HNz | AI181: =VLOOKUP(AH181,'Hess and Brezowsky'!$B$2:$G$31,2,FALSE) -> Meridional | AJ181: =VLOOKUP(AH181,'Hess and Brezowsky'!$B$2:$G$31,3,FALSE) -> C | AK181: =VLOOKUP(AH181,'Hess and Brezowsky'!$B$2:$G$31,4,FALSE) -> Icelandic High, Trough Central Europe | AL181: 0.31240741 | AM181: 0.48819444 | AN181: 0.66398148
A182: 44902 | B182: 2022 | C182: 341 | D182: =WEEKDAY(A182) -> 4 | F182: =IF(G182 > 0.5,1,0)+IF(H182 > 0.5,1,0)+IF(I182 > 0.5,1,0)+IF(J182 > 0.5,1,0)+IF(K182 > 0.5,1,0)+IF(L183 > 0.5,1,0) -> 1 | G182: 0 | H182: 0 | I182: 0 | J182: 0 | K182: 0 | L182: 0 | N182: =IF(AND(M182 > 22.5,M182<=67.6),"NE",IF(AND(M182 > 67.5,M182<=112.5),"E",IF(AND(M182 > 112.5,M182<=157.5),"SE",IF(AND(M182 > 157.5,M182<=202.5),"S",IF(AND(M182 > 202.5,M182<=247.5),"SW",IF(AND(M182 > 247.5,M182<=292.5),"W",IF(AND(M182 > 292.5,M182<=337.5),"NW",IF(AND(M182 > 22.5,M182<=360),"N","N")))))))) -> N | P182: Few | Q182: 0 | R182: 4.32 | S182: 1.3 | T182: 6.5 | U182: 355.6 | V182: N | W182: 0.71 | X182: 0.12 | Y182: 0 | Z182: 0 | AA182: 0 | AB182: 0 | AC182: 0.04 | AD182: 0.12 | AE182: 3.06 | AF182: 2.86 | AG182: 6.5 | AH182: HNz | AI182: =VLOOKUP(AH182,'Hess and Brezowsky'!$B$2:$G$31,2,FALSE) -> Meridional | AJ182: =VLOOKUP(AH182,'Hess and Brezowsky'!$B$2:$G$31,3,FALSE) -> C | AK182: =VLOOKUP(AH182,'Hess and Brezowsky'!$B$2:$G$31,4,FALSE) -> Icelandic High, Trough Central Europe | AL182: 0.31318287 | AM182: 0.4884838 | AN182: 0.66378472
A183: 44903 | B183: 2022 | C183: 342 | D183: =WEEKDAY(A183) -> 5 | F183: =IF(G183 > 0.5,1,0)+IF(H183 > 0.5,1,0)+IF(I183 > 0.5,1,0)+IF(J183 > 0.5,1,0)+IF(K183 > 0.5,1,0)+IF(L184 > 0.5,1,0) -> 3 | G183: 1 | H183: 0 | I183: 1 | J183: 0 | K183: 0 | L183: 1 | M183: 226.359 | N183: =IF(AND(M183 > 22.5,M183<=67.6),"NE",IF(AND(M183 > 67.5,M183<=112.5),"E",IF(AND(M183 > 112.5,M183<=157.5),"SE",IF(AND(M183 > 157.5,M183<=202.5),"S",IF(AND(M183 > 202.5,M183<=247.5),"SW",IF(AND(M183 > 247.5,M183<=292.5),"W",IF(AND(M183 > 292.5,M183<=337.5),"NW",IF(AND(M183 > 22.5,M183<=360),"N","N")))))))) -> SW | O183: 2.4 | P183: Overcast | Q183: 0 | R183: 3.25 | S183: 2.1 | T183: 4.6 | U183: 206.89 | V183: SW | W183: 0.04 | X183: 0.12 | Y183: 0.04 | Z183: 0.04 | AA183: 0.29 | AB183: 0.38 | AC183: 0.04 | AD183: 0.04 | AE183: 1.8 | AF183: 0.67 | AG183: 4.9 | AH183: HNz | AI183: =VLOOKUP(AH183,'Hess and Brezowsky'!$B$2:$G$31,2,FALSE) -> Meridional | AJ183: =VLOOKUP(AH183,'Hess and Brezowsky'!$B$2:$G$31,3,FALSE) -> C | AK183: =VLOOKUP(AH183,'Hess and Brezowsky'!$B$2:$G$31,4,FALSE) -> Icelandic High, Trough Central Europe | AL183: 0.31393519 | AM183: 0.48878472 | AN183: 0.66362269
A184: 44904 | B184: 2022 | C184: 343 | D184: =WEEKDAY(A184) -> 6 | F184: =IF(G184 > 0.5,1,0)+IF(H184 > 0.5,1,0)+IF(I184 > 0.5,1,0)+IF(J184 > 0.5,1,0)+IF(K184 > 0.5,1,0)+IF(L185 > 0.5,1,0) -> 3 | G184: 1 | H184: 0 | I184: 1 | J184: 0 | K184: 0 | L184: 1 | M184: 20.726 | N184: =IF(AND(M184 > 22.5,M184<=67.6),"NE",IF(AND(M184 > 67.5,M184<=112.5),"E",IF(AND(M184 > 112.5,M184<=157.5),"SE",IF(AND(M184 > 157.5,M184<=202.5),"S",IF(AND(M184 > 202.5,M184<=247.5),"SW",IF(AND(M184 > 247.5,M184<=292.5),"W",IF(AND(M184 > 292.5,M184<=337.5),"NW",IF(AND(M184 > 22.5,M184<=360),"N","N")))))))) -> N | O184: 4.4 | P184: Few | Q184: 0 | R184: 2.26 | S184: 0.2 | T184: 3.8 | U184: 19.51 | V184: N | W184: 0.67 | X184: 0.33 | Y184: 0 | Z184: 0 | AA184: 0 | AB184: 0 | AC184: 0 | AD184: 0 | AE184: 3.83 | AF184: 3.61 | AG184: 7.2 | AH184: HNz | AI184: =VLOOKUP(AH184,'Hess and Brezowsky'!$B$2:$G$31,2,FALSE) -> Meridional | AJ184: =VLOOKUP(AH184,'Hess and Brezowsky'!$B$2:$G$31,3,FALSE) -> C | AK184: =VLOOKUP(AH184,'Hess and Brezowsky'!$B$2:$G$31,4,FALSE) -> Icelandic High, Trough Central Europe | AL184: 0.31466435 | AM184: 0.48908565 | AN184: 0.66349537
A185: 44905 | B185: 2022 | C185: 344 | D185: =WEEKDAY(A185) -> 7 | F185: =IF(G185 > 0.5,1,0)+IF(H185 > 0.5,1,0)+IF(I185 > 0.5,1,0)+IF(J185 > 0.5,1,0)+IF(K185 > 0.5,1,0)+IF(L186 > 0.5,1,0) -> 3 | G185: 1 | H185: 0 | I185: 0.95 | J185: 0 | K185: 0 | L185: 1 | M185: 283.9 | N185: =IF(AND(M185 > 22.5,M185<=67.6),"NE",IF(AND(M185 > 67.5,M185<=112.5),"E",IF(AND(M185 > 112.5,M185<=157.5),"SE",IF(AND(M185 > 157.5,M185<=202.5),"S",IF(AND(M185 > 202.5,M185<=247.5),"SW",IF(AND(M185 > 247.5,M185<=292.5),"W",IF(AND(M185 > 292.5,M185<=337.5),"NW",IF(AND(M185 > 22.5,M185<=360),"N","N")))))))) -> W | O185: 3.5 | P185: Broken | Q185: 0 | R185: 1.75 | S185: -0.8 | T185: 4.6 | U185: 291.52 | V185: W | W185: 0.29 | X185: 0 | Y185: 0 | Z185: 0 | AA185: 0.04 | AB185: 0.33 | AC185: 0.21 | AD185: 0.12 | AE185: 2.93 | AF185: 1.52 | AG185: 5.6 | AH185: HNz | AI185: =VLOOKUP(AH185,'Hess and Brezowsky'!$B$2:$G$31,2,FALSE) -> Meridional | AJ185: =VLOOKUP(AH185,'Hess and Brezowsky'!$B$2:$G$31,3,FALSE) -> C | AK185: =VLOOKUP(AH185,'Hess and Brezowsky'!$B$2:$G$31,4,FALSE) -> Icelandic High, Trough Central Europe | AL185: 0.31537037 | AM185: 0.48938657 | AN185: 0.66341435
A186: 44906 | B186: 2022 | C186: 345 | D186: =WEEKDAY(A186) -> 1 | F186: =IF(G186 > 0.5,1,0)+IF(H186 > 0.5,1,0)+IF(I186 > 0.5,1,0)+IF(J186 > 0.5,1,0)+IF(K186 > 0.5,1,0)+IF(L187 > 0.5,1,0) -> 3 | G186: 1 | H186: 0 | I186: 1 | J186: 0 | K186: 0 | L186: 1 | M186: 171.018 | N186: =IF(AND(M186 > 22.5,M186<=67.6),"NE",IF(AND(M186 > 67.5,M186<=112.5),"E",IF(AND(M186 > 112.5,M186<=157.5),"SE",IF(AND(M186 > 157.5,M186<=202.5),"S",IF(AND(M186 > 202.5,M186<=247.5),"SW",IF(AND(M186 > 247.5,M186<=292.5),"W",IF(AND(M186 > 292.5,M186<=337.5),"NW",IF(AND(M186 > 22.5,M186<=360),"N","N")))))))) -> S | O186: 4.1 | P186: Broken | Q186: 0 | R186: -1.41 | S186: -2.3 | T186: 0 | U186: 170.28 | V186: S | W186: 0 | X186: 0 | Y186: 0 | Z186: 0.25 | AA186: 0.75 | AB186: 0 | AC186: 0 | AD186: 0 | AE186: 3.88 | AF186: 3.74 | AG186: 6.3 | AH186: HNz | AI186: =VLOOKUP(AH186,'Hess and Brezowsky'!$B$2:$G$31,2,FALSE) -> Meridional | AJ186: =VLOOKUP(AH186,'Hess and Brezowsky'!$B$2:$G$31,3,FALSE) -> C | AK186: =VLOOKUP(AH186,'Hess and Brezowsky'!$B$2:$G$31,4,FALSE) -> Icelandic High, Trough Central Europe | AL186: 0.31604167 | AM186: 0.48969907 | AN186: 0.66335648
A187: 44907 | B187: 2022 | C187: 346 | D187: =WEEKDAY(A187) -> 2 | F187: =IF(G187 > 0.5,1,0)+IF(H187 > 0.5,1,0)+IF(I187 > 0.5,1,0)+IF(J187 > 0.5,1,0)+IF(K187 > 0.5,1,0)+IF(L188 > 0.5,1,0) -> 3 | G187: 1 | H187: 0 | I187: 1 | J187: 0 | K187: 0 | L187: 1 | M187: 111.902 | N187: =IF(AND(M187 > 22.5,M187<=67.6),"NE",IF(AND(M187 > 67.5,M187<=112.5),"E",IF(AND(M187 > 112.5,M187<=157.5),"SE",IF(AND(M187 > 157.5,M187<=202.5),"S",IF(AND(M187 > 202.5,M187<=247.5),"SW",IF(AND(M187 > 247.5,M187<=292.5),"W",IF(AND(M187 > 292.5,M187<=337.5),"NW",IF(AND(M187 > 22.5,M187<=360),"N","N")))))))) -> E | O187: 5.5 | P187: Broken | Q187: 0 | R187: -1.39 | S187: -2.2 | T187: 0.1 | U187: 115.4 | V187: SE | W187: 0 | X187: 0 | Y187: 0.38 | Z187: 0.62 | AA187: 0 | AB187: 0 | AC187: 0 | AD187: 0 | AE187: 4.92 | AF187: 4.66 | AG187: 9.7 | AH187: HNa | AI187: =VLOOKUP(AH187,'Hess and Brezowsky'!$B$2:$G$31,2,FALSE) -> Meridional | AJ187: =VLOOKUP(AH187,'Hess and Brezowsky'!$B$2:$G$31,3,FALSE) -> A | AK187: =VLOOKUP(AH187,'Hess and Brezowsky'!$B$2:$G$31,4,FALSE) -> Icelandic High, Ride Central Europe | AL187: 0.31668981 | AM187: 0.49001157 | AN187: 0.66333333
A188: 44908 | B188: 2022 | C188: 347 | D188: =WEEKDAY(A188) -> 3 | F188: =IF(G188 > 0.5,1,0)+IF(H188 > 0.5,1,0)+IF(I188 > 0.5,1,0)+IF(J188 > 0.5,1,0)+IF(K188 > 0.5,1,0)+IF(L189 > 0.5,1,0) -> 3 | G188: 1 | H188: 0 | I188: 0.83 | J188: 0 | K188: 0 | L188: 1 | M188: 94.268 | N188: =IF(AND(M188 > 22.5,M188<=67.6),"NE",IF(AND(M188 > 67.5,M188<=112.5),"E",IF(AND(M188 > 112.5,M188<=157.5),"SE",IF(AND(M188 > 157.5,M188<=202.5),"S",IF(AND(M188 > 202.5,M188<=247.5),"SW",IF(AND(M188 > 247.5,M188<=292.5),"W",IF(AND(M188 > 292.5,M188<=337.5),"NW",IF(AND(M188 > 22.5,M188<=360),"N","N")))))))) -> E | O188: 7.5 | P188: Broken | Q188: 0 | R188: -0.56 | S188: -2.7 | T188: 2 | U188: 98.52 | V188: E | W188: 0 | X188: 0 | Y188: 0.79 | Z188: 0.21 | AA188: 0 | AB188: 0 | AC188: 0 | AD188: 0 | AE188: 6.31 | AF188: 6.11 | AG188: 9.2 | AH188: HNa | AI188: =VLOOKUP(AH188,'Hess and Brezowsky'!$B$2:$G$31,2,FALSE) -> Meridional | AJ188: =VLOOKUP(AH188,'Hess and Brezowsky'!$B$2:$G$31,3,FALSE) -> A | AK188: =VLOOKUP(AH188,'Hess and Brezowsky'!$B$2:$G$31,4,FALSE) -> Icelandic High, Ride Central Europe | AL188: 0.31731481 | AM188: 0.49032407 | AN188: 0.66334491
A189: 44909 | B189: 2022 | C189: 348 | D189: =WEEKDAY(A189) -> 4 | F189: =IF(G189 > 0.5,1,0)+IF(H189 > 0.5,1,0)+IF(I189 > 0.5,1,0)+IF(J189 > 0.5,1,0)+IF(K189 > 0.5,1,0)+IF(L190 > 0.5,1,0) -> 3 | G189: 1 | H189: 0 | I189: 1 | J189: 0 | K189: 0 | L189: 1 | M189: 42.065 | N189: =IF(AND(M189 > 22.5,M189<=67.6),"NE",IF(AND(M189 > 67.5,M189<=112.5),"E",IF(AND(M189 > 112.5,M189<=157.5),"SE",IF(AND(M189 > 157.5,M189<=202.5),"S",IF(AND(M189 > 202.5,M189<=247.5),"SW",IF(AND(M189 > 247.5,M189<=292.5),"W",IF(AND(M189 > 292.5,M189<=337.5),"NW",IF(AND(M189 > 22.5,M189<=360),"N","N")))))))) -> NE | O189: 3.6 | P189: Broken | Q189: 0.2 | R189: 0.86 | S189: -0.4 | T189: 2.4 | U189: 39.9 | V189: NE | W189: 0.08 | X189: 0.83 | Y189: 0.04 | Z189: 0.04 | AA189: 0 | AB189: 0 | AC189: 0 | AD189: 0 | AE189: 3.13 | AF189: 2.86 | AG189: 4.7 | AH189: HNa | AI189: =VLOOKUP(AH189,'Hess and Brezowsky'!$B$2:$G$31,2,FALSE) -> Meridional | AJ189: =VLOOKUP(AH189,'Hess and Brezowsky'!$B$2:$G$31,3,FALSE) -> A | AK189: =VLOOKUP(AH189,'Hess and Brezowsky'!$B$2:$G$31,4,FALSE) -> Icelandic High, Ride Central Europe | AL189: 0.31790509 | AM189: 0.49064815 | AN189: 0.6633912
A190: 44910 | B190: 2022 | C190: 349 | D190: =WEEKDAY(A190) -> 5 | F190: =IF(G190 > 0.5,1,0)+IF(H190 > 0.5,1,0)+IF(I190 > 0.5,1,0)+IF(J190 > 0.5,1,0)+IF(K190 > 0.5,1,0)+IF(L191 > 0.5,1,0) -> 3 | G190: 1 | H190: 0 | I190: 0.83 | J190: 0 | K190: 0 | L190: 1 | M190: 42.045 | N190: =IF(AND(M190 > 22.5,M190<=67.6),"NE",IF(AND(M190 > 67.5,M190<=112.5),"E",IF(AND(M190 > 112.5,M190<=157.5),"SE",IF(AND(M190 > 157.5,M190<=202.5),"S",IF(AND(M190 > 202.5,M190<=247.5),"SW",IF(AND(M190 > 247.5,M190<=292.5),"W",IF(AND(M190 > 292.5,M190<=337.5),"NW",IF(AND(M190 > 22.5,M190<=360),"N","N")))))))) -> NE | O190: 8.9 | P190: Broken | Q190: 0 | R190: 0.01 | S190: -2 | T190: 2.4 | U190: 44.12 | V190: NE | W190: 0.04 | X190: 0.88 | Y190: 0.08 | Z190: 0 | AA190: 0 | AB190: 0 | AC190: 0 | AD190: 0 | AE190: 9.85 | AF190: 9.55 | AG190: 17 | AH190: TrM | AI190: =VLOOKUP(AH190,'Hess and Brezowsky'!$B$2:$G$31,2,FALSE) -> Meridional | AJ190: =VLOOKUP(AH190,'Hess and Brezowsky'!$B$2:$G$31,3,FALSE) -> M | AK190: =VLOOKUP(AH190,'Hess and Brezowsky'!$B$2:$G$31,4,FALSE) -> Trough over Central Europe | AL190: 0.31847222 | AM190: 0.49097222 | AN190: 0.66347222
A191: 44911 | B191: 2022 | C191: 350 | D191: =WEEKDAY(A191) -> 6 | F191: =IF(G191 > 0.5,1,0)+IF(H191 > 0.5,1,0)+IF(I191 > 0.5,1,0)+IF(J191 > 0.5,1,0)+IF(K191 > 0.5,1,0)+IF(L192 > 0.5,1,0) -> 3 | G191: 1 | H191: 0 | I191: 0.91 | J191: 0 | K191: 0 | L191: 1 | M191: 28.987 | N191: =IF(AND(M191 > 22.5,M191<=67.6),"NE",IF(AND(M191 > 67.5,M191<=112.5),"E",IF(AND(M191 > 112.5,M191<=157.5),"SE",IF(AND(M191 > 157.5,M191<=202.5),"S",IF(AND(M191 > 202.5,M191<=247.5),"SW",IF(AND(M191 > 247.5,M191<=292.5),"W",IF(AND(M191 > 292.5,M191<=337.5),"NW",IF(AND(M191 > 22.5,M191<=360),"N","N")))))))) -> NE | O191: 6.7 | P191: Few | Q191: 0 | R191: 0.05 | S191: -1.6 | T191: 1.6 | U191: 26.46 | V191: NE | W191: 0.38 | X191: 0.54 | Y191: 0.08 | Z191: 0 | AA191: 0 | AB191: 0 | AC191: 0 | AD191: 0 | AE191: 7.18 | AF191: 6.91 | AG191: 13.1 | AH191: TrM | AI191: =VLOOKUP(AH191,'Hess and Brezowsky'!$B$2:$G$31,2,FALSE) -> Meridional | AJ191: =VLOOKUP(AH191,'Hess and Brezowsky'!$B$2:$G$31,3,FALSE) -> M | AK191: =VLOOKUP(AH191,'Hess and Brezowsky'!$B$2:$G$31,4,FALSE) -> Trough over Central Europe | AL191: 0.31900463 | AM191: 0.4912963 | AN191: 0.66358796
A192: 44912 | B192: 2022 | C192: 351 | D192: =WEEKDAY(A192) -> 7 | F192: =IF(G192 > 0.5,1,0)+IF(H192 > 0.5,1,0)+IF(I192 > 0.5,1,0)+IF(J192 > 0.5,1,0)+IF(K192 > 0.5,1,0)+IF(L193 > 0.5,1,0) -> 3 | G192: 1 | H192: 0 | I192: 1 | J192: 0 | K192: 0 | L192: 1 | M192: 116.603 | N192: =IF(AND(M192 > 22.5,M192<=67.6),"NE",IF(AND(M192 > 67.5,M192<=112.5),"E",IF(AND(M192 > 112.5,M192<=157.5),"SE",IF(AND(M192 > 157.5,M192<=202.5),"S",IF(AND(M192 > 202.5,M192<=247.5),"SW",IF(AND(M192 > 247.5,M192<=292.5),"W",IF(AND(M192 > 292.5,M192<=337.5),"NW",IF(AND(M192 > 22.5,M192<=360),"N","N")))))))) -> SE | O192: 4.2 | P192: Broken | Q192: 0 | R192: -1.68 | S192: -4.4 | T192: -0.4 | U192: 125.19 | V192: SE | W192: 0 | X192: 0 | Y192: 0.21 | Z192: 0.79 | AA192: 0 | AB192: 0 | AC192: 0 | AD192: 0 | AE192: 4.06 | AF192: 3.98 | AG192: 11.9 | AH192: TrM | AI192: =VLOOKUP(AH192,'Hess and Brezowsky'!$B$2:$G$31,2,FALSE) -> Meridional | AJ192: =VLOOKUP(AH192,'Hess and Brezowsky'!$B$2:$G$31,3,FALSE) -> M | AK192: =VLOOKUP(AH192,'Hess and Brezowsky'!$B$2:$G$31,4,FALSE) -> Trough over Central Europe | AL192: 0.31950231 | AM192: 0.49162037 | AN192: 0.66373843
A193: 44913 | B193: 2022 | C193: 352 | D193: =WEEKDAY(A193) -> 1 | F193: =IF(G193 > 0.5,1,0)+IF(H193 > 0.5,1,0)+IF(I193 > 0.5,1,0)+IF(J193 > 0.5,1,0)+IF(K193 > 0.5,1,0)+IF(L194 > 0.5,1,0) -> 3 | G193: 1 | H193: 0 | I193: 1 | J193: 0 | K193: 0 | L193: 1 | M193: 169.608 | N193: =IF(AND(M193 > 22.5,M193<=67.6),"NE",IF(AND(M193 > 67.5,M193<=112.5),"E",IF(AND(M193 > 112.5,M193<=157.5),"SE",IF(AND(M193 > 157.5,M193<=202.5),"S",IF(AND(M193 > 202.5,M193<=247.5),"SW",IF(AND(M193 > 247.5,M193<=292.5),"W",IF(AND(M193 > 292.5,M193<=337.5),"NW",IF(AND(M193 > 22.5,M193<=360),"N","N")))))))) -> S | O193: 11 | P193: Broken | Q193: 4.2 | R193: -1.15 | S193: -5 | T193: 4.5 | U193: 176.22 | V193: S | W193: 0 | X193: 0 | Y193: 0 | Z193: 0.17 | AA193: 0.83 | AB193: 0 | AC193: 0 | AD193: 0 | AE193: 12.95 | AF193: 12.25 | AG193: 18 | AH193: SWz | AI193: =VLOOKUP(AH193,'Hess and Brezowsky'!$B$2:$G$31,2,FALSE) -> Mixed | AJ193: =VLOOKUP(AH193,'Hess and Brezowsky'!$B$2:$G$31,3,FALSE) -> C | AK193: =VLOOKUP(AH193,'Hess and Brezowsky'!$B$2:$G$31,4,FALSE) -> Cyclonic South-Westerly | AL193: 0.31997685 | AM193: 0.49195602 | AN193: 0.66392361
A194: 44914 | B194: 2022 | C194: 353 | D194: =WEEKDAY(A194) -> 2 | F194: =IF(G194 > 0.5,1,0)+IF(H194 > 0.5,1,0)+IF(I194 > 0.5,1,0)+IF(J194 > 0.5,1,0)+IF(K194 > 0.5,1,0)+IF(L195 > 0.5,1,0) -> 3 | G194: 1 | H194: 0 | I194: 1 | J194: 0 | K194: 0 | L194: 1 | M194: 199.558 | N194: =IF(AND(M194 > 22.5,M194<=67.6),"NE",IF(AND(M194 > 67.5,M194<=112.5),"E",IF(AND(M194 > 112.5,M194<=157.5),"SE",IF(AND(M194 > 157.5,M194<=202.5),"S",IF(AND(M194 > 202.5,M194<=247.5),"SW",IF(AND(M194 > 247.5,M194<=292.5),"W",IF(AND(M194 > 292.5,M194<=337.5),"NW",IF(AND(M194 > 22.5,M194<=360),"N","N")))))))) -> S | O194: 13.5 | P194: Overcast | Q194: 0.8 | R194: 9.05 | S194: 4.5 | T194: 12.4 | U194: 199.19 | V194: S | W194: 0 | X194: 0 | Y194: 0 | Z194: 0 | AA194: 1 | AB194: 0 | AC194: 0 | AD194: 0 | AE194: 13.64 | AF194: 13.63 | AG194: 17.5 | AH194: SWz | AI194: =VLOOKUP(AH194,'Hess and Brezowsky'!$B$2:$G$31,2,FALSE) -> Mixed | AJ194: =VLOOKUP(AH194,'Hess and Brezowsky'!$B$2:$G$31,3,FALSE) -> C | AK194: =VLOOKUP(AH194,'Hess and Brezowsky'!$B$2:$G$31,4,FALSE) -> Cyclonic South-Westerly | AL194: 0.32041667 | AM194: 0.49228009 | AN194: 0.66415509
... A206: 44926 | B206: 2022 | C206: 365 | D206: =WEEKDAY(A206) -> 7 | F206: =IF(G206 > 0.5,1,0)+IF(H206 > 0.5,1,0)+IF(I206 > 0.5,1,0)+IF(J206 > 0.5,1,0)+IF(K206 > 0.5,1,0)+IF(L207 > 0.5,1,0) -> 3 | G206: 1 | H206: 0 | I206: 1 | J206: 0 | K206: 0 | L206: 1 | M206: 210.805 | N206: =IF(AND(M206 > 22.5,M206<=67.6),"NE",IF(AND(M206 > 67.5,M206<=112.5),"E",IF(AND(M206 > 112.5,M206<=157.5),"SE",IF(AND(M206 > 157.5,M206<=202.5),"S",IF(AND(M206 > 202.5,M206<=247.5),"SW",IF(AND(M206 > 247.5,M206<=292.5),"W",IF(AND(M206 > 292.5,M206<=337.5),"NW",IF(AND(M206 > 22.5,M206<=360),"N","N")))))))) -> SW | O206: 15.8 | P206: Overcast | Q206: 0.2 | R206: 15.23 | S206: 14.2 | T206: 16.1 | U206: 204.36 | V206: SW | W206: 0 | X206: 0 | Y206: 0 | Z206: 0 | AA206: 0.46 | AB206: 0.54 | AC206: 0 | AD206: 0 | AE206: 14.9 | AF206: 14.86 | AG206: 19.9 | AH206: SWz | AI206: =VLOOKUP(AH206,'Hess and Brezowsky'!$B$2:$G$31,2,FALSE) -> Mixed | AJ206: =VLOOKUP(AH206,'Hess and Brezowsky'!$B$2:$G$31,3,FALSE) -> C | AK206: =VLOOKUP(AH206,'Hess and Brezowsky'!$B$2:$G$31,4,FALSE) -> Cyclonic South-Westerly | AL206: 0.323125 | AM206: 0.49626157 | AN206: 0.66940972
A207: 44927 | B207: 2023 | C207: 1 | D207: =WEEKDAY(A207) -> 1 | F207: =IF(G207 > 0.5,1,0)+IF(H207 > 0.5,1,0)+IF(I207 > 0.5,1,0)+IF(J207 > 0.5,1,0)+IF(K207 > 0.5,1,0)+IF(L208 > 0.5,1,0) -> 3 | G207: 1 | H207: 0 | I207: 1 | J207: 0 | K207: 0 | L207: 1 | M207: 201.631 | N207: =IF(AND(M207 > 22.5,M207<=67.6),"NE",IF(AND(M207 > 67.5,M207<=112.5),"E",IF(AND(M207 > 112.5,M207<=157.5),"SE",IF(AND(M207 > 157.5,M207<=202.5),"S",IF(AND(M207 > 202.5,M207<=247.5),"SW",IF(AND(M207 > 247.5,M207<=292.5),"W",IF(AND(M207 > 292.5,M207<=337.5),"NW",IF(AND(M207 > 22.5,M207<=360),"N","N")))))))) -> S | O207: 12.5 | Q207: 1.4 | R207: 13.07 | S207: 11.4 | T207: 15 | U207: 196.17 | V207: S | W207: 0 | X207: 0 | Y207: 0 | Z207: 0 | AA207: 0.62 | AB207: 0.38 | AC207: 0 | AD207: 0 | AE207: 11.68 | AF207: 11.21 | AG207: 15.9 | AH207: SWz | AI207: =VLOOKUP(AH207,'Hess and Brezowsky'!$B$2:$G$31,2,FALSE) -> Mixed | AJ207: =VLOOKUP(AH207,'Hess and Brezowsky'!$B$2:$G$31,3,FALSE) -> C | AK207: =VLOOKUP(AH207,'Hess and Brezowsky'!$B$2:$G$31,4,FALSE) -> Cyclonic South-Westerly | AL207: 0.323125 | AM207: 0.49658565 | AN207: 0.6700463
A208: 44928 | B208: 2023 | C208: 2 | D208: =WEEKDAY(A208) -> 2 | F208: =IF(G208 > 0.5,1,0)+IF(H208 > 0.5,1,0)+IF(I208 > 0.5,1,0)+IF(J208 > 0.5,1,0)+IF(K208 > 0.5,1,0)+IF(L209 > 0.5,1,0) -> 3 | G208: 1 | H208: 0 | I208: 0.7 | J208: 0 | K208: 0 | L208: 1 | M208: 233.298 | N208: =IF(AND(M208 > 22.5,M208<=67.6),"NE",IF(AND(M208 > 67.5,M208<=112.5),"E",IF(AND(M208 > 112.5,M208<=157.5),"SE",IF(AND(M208 > 157.5,M208<=202.5),"S",IF(AND(M208 > 202.5,M208<=247.5),"SW",IF(AND(M208 > 247.5,M208<=292.5),"W",IF(AND(M208 > 292.5,M208<=337.5),"NW",IF(AND(M208 > 22.5,M208<=360),"N","N")))))))) -> SW | O208: 9.3 | P208: Broken | Q208: 5.4 | R208: 10.4 | S208: 6.7 | T208: 14.3 | U208: 234.35 | V208: SW | W208: 0 | X208: 0 | Y208: 0 | Z208: 0 | AA208: 0 | AB208: 0.96 | AC208: 0.04 | AD208: 0 | AE208: 8.42 | AF208: 8.35 | AG208: 13.1 | AH208: SWz | AI208: =VLOOKUP(AH208,'Hess and Brezowsky'!$B$2:$G$31,2,FALSE) -> Mixed | AJ208: =VLOOKUP(AH208,'Hess and Brezowsky'!$B$2:$G$31,3,FALSE) -> C | AK208: =VLOOKUP(AH208,'Hess and Brezowsky'!$B$2:$G$31,4,FALSE) -> Cyclonic South-Westerly | AL208: 0.32309028 | AM208: 0.49690972 | AN208: 0.67071759
A209: 44929 | B209: 2023 | C209: 3 | D209: =WEEKDAY(A209) -> 3 | F209: =IF(G209 > 0.5,1,0)+IF(H209 > 0.5,1,0)+IF(I209 > 0.5,1,0)+IF(J209 > 0.5,1,0)+IF(K209 > 0.5,1,0)+IF(L210 > 0.5,1,0) -> 3 | G209: 1 | H209: 0 | I209: 0.87 | J209: 0 | K209: 0 | L209: 1 | M209: 211.726 | N209: =IF(AND(M209 > 22.5,M209<=67.6),"NE",IF(AND(M209 > 67.5,M209<=112.5),"E",IF(AND(M209 > 112.5,M209<=157.5),"SE",IF(AND(M209 > 157.5,M209<=202.5),"S",IF(AND(M209 > 202.5,M209<=247.5),"SW",IF(AND(M209 > 247.5,M209<=292.5),"W",IF(AND(M209 > 292.5,M209<=337.5),"NW",IF(AND(M209 > 22.5,M209<=360),"N","N")))))))) -> SW | O209: 9.6 | P209: Overcast | Q209: 2 | R209: 7.91 | S209: 5.4 | T209: 10 | U209: 211.6 | V209: SW | W209: 0 | X209: 0 | Y209: 0 | Z209: 0 | AA209: 0.33 | AB209: 0.67 | AC209: 0 | AD209: 0 | AE209: 9.09 | AF209: 8.8 | AG209: 14.2 | AH209: Wz | AI209: =VLOOKUP(AH209,'Hess and Brezowsky'!$B$2:$G$31,2,FALSE) -> Zonal | AJ209: =VLOOKUP(AH209,'Hess and Brezowsky'!$B$2:$G$31,3,FALSE) -> C | AK209: =VLOOKUP(AH209,'Hess and Brezowsky'!$B$2:$G$31,4,FALSE) -> Cyclonic Westerly | AL209: 0.32303241 | AM209: 0.49722222 | AN209: 0.67141204
A210: 44930 | B210: 2023 | C210: 4 | D210: =WEEKDAY(A210) -> 4 | F210: =IF(G210 > 0.5,1,0)+IF(H210 > 0.5,1,0)+IF(I210 > 0.5,1,0)+IF(J210 > 0.5,1,0)+IF(K210 > 0.5,1,0)+IF(L211 > 0.5,1,0) -> 3 | G210: 1 | H210: 0 | I210: 1 | J210: 0 | K210: 0 | L210: 1 | M210: 230.747 | N210: =IF(AND(M210 > 22.5,M210<=67.6),"NE",IF(AND(M210 > 67.5,M210<=112.5),"E",IF(AND(M210 > 112.5,M210<=157.5),"SE",IF(AND(M210 > 157.5,M210<=202.5),"S",IF(AND(M210 > 202.5,M210<=247.5),"SW",IF(AND(M210 > 247.5,M210<=292.5),"W",IF(AND(M210 > 292.5,M210<=337.5),"NW",IF(AND(M210 > 22.5,M210<=360),"N","N")))))))) -> SW | O210: 13.2 | P210: Overcast | Q210: 0.8 | R210: 12.01 | S210: 10 | T210: 13.6 | U210: 229.55 | V210: SW | W210: 0 | X210: 0 | Y210: 0 | Z210: 0 | AA210: 0 | AB210: 0.92 | AC210: 0.08 | AD210: 0 | AE210: 11.8 | AF210: 11.56 | AG210: 15.6 | AH210: Wz | AI210: =VLOOKUP(AH210,'Hess and Brezowsky'!$B$2:$G$31,2,FALSE) -> Zonal | AJ210: =VLOOKUP(AH210,'Hess and Brezowsky'!$B$2:$G$31,3,FALSE) -> C | AK210: =VLOOKUP(AH210,'Hess and Brezowsky'!$B$2:$G$31,4,FALSE) -> Cyclonic Westerly | AL210: 0.32292824 | AM210: 0.49753472 | AN210: 0.6721412
A211: 44931 | B211: 2023 | C211: 5 | D211: =WEEKDAY(A211) -> 5 | F211: =IF(G211 > 0.5,1,0)+IF(H211 > 0.5,1,0)+IF(I211 > 0.5,1,0)+IF(J211 > 0.5,1,0)+IF(K211 > 0.5,1,0)+IF(L212 > 0.5,1,0) -> 3 | G211: 1 | H211: 0 | I211: 1 | J211: 0 | K211: 0 | L211: 1 | M211: 253.478 | N211: =IF(AND(M211 > 22.5,M211<=67.6),"NE",IF(AND(M211 > 67.5,M211<=112.5),"E",IF(AND(M211 > 112.5,M211<=157.5),"SE",IF(AND(M211 > 157.5,M211<=202.5),"S",IF(AND(M211 > 202.5,M211<=247.5),"SW",IF(AND(M211 > 247.5,M211<=292.5),"W",IF(AND(M211 > 292.5,M211<=337.5),"NW",IF(AND(M211 > 22.5,M211<=360),"N","N")))))))) -> W | O211: 8.7 | P211: Overcast | Q211: 0.2 | R211: 12.64 | S211: 11 | T211: 13.9 | U211: 252.83 | V211: W | W211: 0 | X211: 0 | Y211: 0 | Z211: 0 | AA211: 0 | AB211: 0.42 | AC211: 0.58 | AD211: 0 | AE211: 9 | AF211: 8.69 | AG211: 14.9 | AH211: Wz | AI211: =VLOOKUP(AH211,'Hess and Brezowsky'!$B$2:$G$31,2,FALSE) -> Zonal | AJ211: =VLOOKUP(AH211,'Hess and Brezowsky'!$B$2:$G$31,3,FALSE) -> C | AK211: =VLOOKUP(AH211,'Hess and Brezowsky'!$B$2:$G$31,4,FALSE) -> Cyclonic Westerly | AL211: 0.32278935 | AM211: 0.49783565 | AN211: 0.67288194
A212: 44932 | B212: 2023 | C212: 6 | D212: =WEEKDAY(A212) -> 6 | F212: =IF(G212 > 0.5,1,0)+IF(H212 > 0.5,1,0)+IF(I212 > 0.5,1,0)+IF(J212 > 0.5,1,0)+IF(K212 > 0.5,1,0)+IF(L213 > 0.5,1,0) -> 3 | G212: 1 | H212: 0 | I212: 1 | J212: 0 | K212: 0 | L212: 1 | M212: 217.958 | N212: =IF(AND(M212 > 22.5,M212<=67.6),"NE",IF(AND(M212 > 67.5,M212<=112.5),"E",IF(AND(M212 > 112.5,M212<=157.5),"SE",IF(AND(M212 > 157.5,M212<=202.5),"S",IF(AND(M212 > 202.5,M212<=247.5),"SW",IF(AND(M212 > 247.5,M212<=292.5),"W",IF(AND(M212 > 292.5,M212<=337.5),"NW",IF(AND(M212 > 22.5,M212<=360),"N","N")))))))) -> SW | O212: 8.8 | P212: Broken | Q212: 0 | R212: 11.53 | S212: 10.5 | T212: 13.4 | U212: 214.47 | V212: SW | W212: 0 | X212: 0 | Y212: 0 | Z212: 0 | AA212: 0.21 | AB212: 0.79 | AC212: 0 | AD212: 0 | AE212: 7.18 | AF212: 7.06 | AG212: 10.3 | AH212: SWz | AI212: =VLOOKUP(AH212,'Hess and Brezowsky'!$B$2:$G$31,2,FALSE) -> Mixed | AJ212: =VLOOKUP(AH212,'Hess and Brezowsky'!$B$2:$G$31,3,FALSE) -> C | AK212: =VLOOKUP(AH212,'Hess and Brezowsky'!$B$2:$G$31,4,FALSE) -> Cyclonic South-Westerly | AL212: 0.32262731 | AM212: 0.49814815 | AN212: 0.67365741
A213: 44933 | B213: 2023 | C213: 7 | D213: =WEEKDAY(A213) -> 7 | F213: =IF(G213 > 0.5,1,0)+IF(H213 > 0.5,1,0)+IF(I213 > 0.5,1,0)+IF(J213 > 0.5,1,0)+IF(K213 > 0.5,1,0)+IF(L214 > 0.5,1,0) -> 3 | G213: 1 | H213: 0 | I213: 0.79 | J213: 0 | K213: 0 | L213: 1 | M213: 198.484 | N213: =IF(AND(M213 > 22.5,M213<=67.6),"NE",IF(AND(M213 > 67.5,M213<=112.5),"E",IF(AND(M213 > 112.5,M213<=157.5),"SE",IF(AND(M213 > 157.5,M213<=202.5),"S",IF(AND(M213 > 202.5,M213<=247.5),"SW",IF(AND(M213 > 247.5,M213<=292.5),"W",IF(AND(M213 > 292.5,M213<=337.5),"NW",IF(AND(M213 > 22.5,M213<=360),"N","N")))))))) -> S | O213: 12 | P213: Broken | Q213: 1 | R213: 10.04 | S213: 7.6 | T213: 11.4 | U213: 194.69 | V213: S | W213: 0 | X213: 0 | Y213: 0 | Z213: 0 | AA213: 0.92 | AB213: 0.08 | AC213: 0 | AD213: 0 | AE213: 11.51 | AF213: 11.42 | AG213: 14.4 | AH213: SWz | AI213: =VLOOKUP(AH213,'Hess and Brezowsky'!$B$2:$G$31,2,FALSE) -> Mixed | AJ213: =VLOOKUP(AH213,'Hess and Brezowsky'!$B$2:$G$31,3,FALSE) -> C | AK213: =VLOOKUP(AH213,'Hess and Brezowsky'!$B$2:$G$31,4,FALSE) -> Cyclonic South-Westerly | AL213: 0.32241898 | AM213: 0.4984375 | AN213: 0.67445602
A214: 44934 | B214: 2023 | C214: 8 | D214: =WEEKDAY(A214) -> 1 | F214: =IF(G214 > 0.5,1,0)+IF(H214 > 0.5,1,0)+IF(I214 > 0.5,1,0)+IF(J214 > 0.5,1,0)+IF(K214 > 0.5,1,0)+IF(L215 > 0.5,1,0) -> 3 | G214: 1 | H214: 0 | I214: 0.95 | J214: 0 | K214: 0 | L214: 1 | M214: 216.852 | N214: =IF(AND(M214 > 22.5,M214<=67.6),"NE",IF(AND(M214 > 67.5,M214<=112.5),"E",IF(AND(M214 > 112.5,M214<=157.5),"SE",IF(AND(M214 > 157.5,M214<=202.5),"S",IF(AND(M214 > 202.5,M214<=247.5),"SW",IF(AND(M214 > 247.5,M214<=292.5),"W",IF(AND(M214 > 292.5,M214<=337.5),"NW",IF(AND(M214 > 22.5,M214<=360),"N","N")))))))) -> SW | O214: 11.7 | P214: Broken | Q214: 2.2 | R214: 9.36 | S214: 6.6 | T214: 11.1 | U214: 213.09 | V214: SW | W214: 0 | X214: 0 | Y214: 0 | Z214: 0 | AA214: 0.38 | AB214: 0.58 | AC214: 0.04 | AD214: 0 | AE214: 10.95 | AF214: 10.51 | AG214: 15.2 | AH214: SWz | AI214: =VLOOKUP(AH214,'Hess and Brezowsky'!$B$2:$G$31,2,FALSE) -> Mixed | AJ214: =VLOOKUP(AH214,'Hess and Brezowsky'!$B$2:$G$31,3,FALSE) -> C | AK214: =VLOOKUP(AH214,'Hess and Brezowsky'!$B$2:$G$31,4,FALSE) -> Cyclonic South-Westerly | AL214: 0.3221875 | AM214: 0.49873843 | AN214: 0.67528935
A215: 44935 | B215: 2023 | C215: 9 | D215: =WEEKDAY(A215) -> 2 | F215: =IF(G215 > 0.5,1,0)+IF(H215 > 0.5,1,0)+IF(I215 > 0.5,1,0)+IF(J215 > 0.5,1,0)+IF(K215 > 0.5,1,0)+IF(L216 > 0.5,1,0) -> 3 | G215: 1 | H215: 0 | I215: 1 | J215: 0 | K215: 0 | L215: 1 | M215: 257.855 | N215: =IF(AND(M215 > 22.5,M215<=67.6),"NE",IF(AND(M215 > 67.5,M215<=112.5),"E",IF(AND(M215 > 112.5,M215<=157.5),"SE",IF(AND(M215 > 157.5,M215<=202.5),"S",IF(AND(M215 > 202.5,M215<=247.5),"SW",IF(AND(M215 > 247.5,M215<=292.5),"W",IF(AND(M215 > 292.5,M215<=337.5),"NW",IF(AND(M215 > 22.5,M215<=360),"N","N")))))))) -> W | O215: 12 | P215: Broken | Q215: 4.2 | R215: 7.23 | S215: 5.6 | T215: 9.5 | U215: 259.21 | V215: W | W215: 0 | X215: 0 | Y215: 0 | Z215: 0 | AA215: 0 | AB215: 0.33 | AC215: 0.67 | AD215: 0 | AE215: 14.25 | AF215: 13.5 | AG215: 19.6 | AH215: SWz | AI215: =VLOOKUP(AH215,'Hess and Brezowsky'!$B$2:$G$31,2,FALSE) -> Mixed | AJ215: =VLOOKUP(AH215,'Hess and Brezowsky'!$B$2:$G$31,3,FALSE) -> C | AK215: =VLOOKUP(AH215,'Hess and Brezowsky'!$B$2:$G$31,4,FALSE) -> Cyclonic South-Westerly | AL215: 0.3219213 | AM215: 0.49902778 | AN215: 0.67613426
A216: 44936 | B216: 2023 | C216: 10 | D216: =WEEKDAY(A216) -> 3 | F216: =IF(G216 > 0.5,1,0)+IF(H216 > 0.5,1,0)+IF(I216 > 0.5,1,0)+IF(J216 > 0.5,1,0)+IF(K216 > 0.5,1,0)+IF(L217 > 0.5,1,0) -> 2 | G216: 0 | H216: 0 | I216: 1 | J216: 0 | K216: 0 | L216: 1 | M216: 219.239 | N216: =IF(AND(M216 > 22.5,M216<=67.6),"NE",IF(AND(M216 > 67.5,M216<=112.5),"E",IF(AND(M216 > 112.5,M216<=157.5),"SE",IF(AND(M216 > 157.5,M216<=202.5),"S",IF(AND(M216 > 202.5,M216<=247.5),"SW",IF(AND(M216 > 247.5,M216<=292.5),"W",IF(AND(M216 > 292.5,M216<=337.5),"NW",IF(AND(M216 > 22.5,M216<=360),"N","N")))))))) -> SW | O216: 11 | P216: Overcast | Q216: 2.6 | R216: 7.47 | S216: 4.3 | T216: 12 | U216: 219.26 | V216: SW | W216: 0 | X216: 0 | Y216: 0 | Z216: 0 | AA216: 0.33 | AB216: 0.46 | AC216: 0.21 | AD216: 0 | AE216: 11.56 | AF216: 10.44 | AG216: 14.7 | AH216: Ww | AI216: =VLOOKUP(AH216,'Hess and Brezowsky'!$B$2:$G$31,2,FALSE) -> Zonal | AJ216: =VLOOKUP(AH216,'Hess and Brezowsky'!$B$2:$G$31,3,FALSE) -> M | AK216: =VLOOKUP(AH216,'Hess and Brezowsky'!$B$2:$G$31,4,FALSE) -> Maritime Westerly (Block Eastern Europe) | AL216: 0.32162037 | AM216: 0.49930556 | AN216: 0.67700231
A217: 44937 | B217: 2023 | C217: 11 | D217: =WEEKDAY(A217) -> 4 | F217: =IF(G217 > 0.5,1,0)+IF(H217 > 0.5,1,0)+IF(I217 > 0.5,1,0)+IF(J217 > 0.5,1,0)+IF(K217 > 0.5,1,0)+IF(L218 > 0.5,1,0) -> 2 | G217: 0 | H217: 0 | I217: 0.95 | J217: 0 | K217: 0 | L217: 1 | M217: 241.721 | N217: =IF(AND(M217 > 22.5,M217<=67.6),"NE",IF(AND(M217 > 67.5,M217<=112.5),"E",IF(AND(M217 > 112.5,M217<=157.5),"SE",IF(AND(M217 > 157.5,M217<=202.5),"S",IF(AND(M217 > 202.5,M217<=247.5),"SW",IF(AND(M217 > 247.5,M217<=292.5),"W",IF(AND(M217 > 292.5,M217<=337.5),"NW",IF(AND(M217 > 22.5,M217<=360),"N","N")))))))) -> SW | O217: 10.9 | P217: Broken | Q217: 3.8 | R217: 10.78 | S217: 9.3 | T217: 12.2 | U217: 242.19 | V217: SW | W217: 0 | X217: 0 | Y217: 0 | Z217: 0 | AA217: 0 | AB217: 0.62 | AC217: 0.38 | AD217: 0 | AE217: 11.96 | AF217: 11.15 | AG217: 14.9 | AH217: Ww | AI217: =VLOOKUP(AH217,'Hess and Brezowsky'!$B$2:$G$31,2,FALSE) -> Zonal | AJ217: =VLOOKUP(AH217,'Hess and Brezowsky'!$B$2:$G$31,3,FALSE) -> M | AK217: =VLOOKUP(AH217,'Hess and Brezowsky'!$B$2:$G$31,4,FALSE) -> Maritime Westerly (Block Eastern Europe) | AL217: 0.32128472 | AM217: 0.49958333 | AN217: 0.67789352
A218: 44938 | B218: 2023 | C218: 12 | D218: =WEEKDAY(A218) -> 5 | F218: =IF(G218 > 0.5,1,0)+IF(H218 > 0.5,1,0)+IF(I218 > 0.5,1,0)+IF(J218 > 0.5,1,0)+IF(K218 > 0.5,1,0)+IF(L219 > 0.5,1,0) -> 3 | G218: 1 | H218: 0 | I218: 1 | J218: 0 | K218: 0 | L218: 1 | M218: 224.744 | N218: =IF(AND(M218 > 22.5,M218<=67.6),"NE",IF(AND(M218 > 67.5,M218<=112.5),"E",IF(AND(M218 > 112.5,M218<=157.5),"SE",IF(AND(M218 > 157.5,M218<=202.5),"S",IF(AND(M218 > 202.5,M218<=247.5),"SW",IF(AND(M218 > 247.5,M218<=292.5),"W",IF(AND(M218 > 292.5,M218<=337.5),"NW",IF(AND(M218 > 22.5,M218<=360),"N","N")))))))) -> SW | O218: 13.5 | P218: Overcast | Q218: 1.2 | R218: 10.86 | S218: 9.6 | T218: 11.8 | U218: 225.53 | V218: SW | W218: 0 | X218: 0 | Y218: 0 | Z218: 0 | AA218: 0 | AB218: 1 | AC218: 0 | AD218: 0 | AE218: 11.65 | AF218: 11.62 | AG218: 15.2 | AH218: Ww | AI218: =VLOOKUP(AH218,'Hess and Brezowsky'!$B$2:$G$31,2,FALSE) -> Zonal | AJ218: =VLOOKUP(AH218,'Hess and Brezowsky'!$B$2:$G$31,3,FALSE) -> M | AK218: =VLOOKUP(AH218,'Hess and Brezowsky'!$B$2:$G$31,4,FALSE) -> Maritime Westerly (Block Eastern Europe) | AL218: 0.32091435 | AM218: 0.49986111 | AN218: 0.6787963
...

Sheet Data Sources
A1: This document is part of
A2: Harmonised boundary layer wind profile dataset from six ground-based doppler wind lidars in a transect across Paris (France) from 2022-06-10 to 2024-03-05
A3: The doppler wind lidar (DWL) dataset can be found at https://doi.org/10.5281/zenodo.15090857
A5: Data from Eiffel Tower and Montsouris are provided by MeteoFrance. Data has been further aggregated.
A6: The synoptic classification for Europe "Grosswetterlagen" is provided by DWD as part of open data (https://www.dwd.de/DE/leistungen/grosswetterlage/2023/grosswetterlage.html)
A7: Solar radiation is a subject classification based on global hemispherical radiation data from BSRN Site PAL, and urbisphere sites PACHEM, PADENF, PACOUR, PACHAN, PANANG, PACOUR, PAAUNA, PAPRUN, PAWYDT, PASTFE
A8: The use of the work is at the user's own risk. The authors, the involved institutions, and/or the European Commission accept no liability for material or non-material damage arising from the use or non-use or from the use of incorrect or incomplete information in this work. The authors, the involved institutions, and/or the European Research Commission are not responsible for any use that may be made of the information in this work. The legal provisions remain unaffected.

Sheet Hess and Brezowsky
A1: Number | B1: ID | C1: Synoptic type | D1: Cyclonic, Anticyclonic, Mixed | E1: Description English (James, 2007) | F1: Description (German, original)
A2: 1 | B2: Wa | C2: Zonal | D2: A | E2: Anticyclonic Westerly | F2: Westlage, Mitteleuropa überwiegend antizyklonal
A3: 2 | B3: Wz | C3: Zonal | D3: C | E3: Cyclonic Westerly | F3: Westlage, Mitteleuropa überwiegend zyklonal
A4: 3 | B4: WS | C4: Zonal | D4: M | E4: South-Shifted Westerly | F4: Südliche Westlage
A5: 4 | B5: WW | C5: Zonal | D5: M | E5: Maritime Westerly (Block Eastern Europe) | F5: Winkelförmige Westlage
A6: 5 | B6: SWa | C6: Mixed | D6: A | E6: Anticyclonic South-Westerly | F6: Südwestlage, Mitteleuropa überwiegend antizyklonal
A7: 6 | B7: SWz | C7: Mixed | D7: C | E7: Cyclonic South-Westerly | F7: Südwestlage, Mitteleuropa überwiegend zyklonal
A8: 7 | B8: NWa | C8: Mixed | D8: A | E8: Anticyclonic North-Westerly | F8: Nordwestlage, Mitteleuropa überwiegend antizyklonal
A9: 8 | B9: NWz | C9: Mixed | D9: C | E9: Cyclonic North-Westerly | F9: Nordwestlage, Mitteleuropa überwiegend zyklonal
A10: 9 | B10: HM | C10: Mixed | D10: A | E10: High over Central Europe | F10: Hoch Mitteleuropa
A11: 10 | B11: BM | C11: Mixed | D11: A | E11: Zonal Ridge across Central Europe | F11: Hochdruckbrücke Mitteleuropa
A12: 11 | B12: TM | C12: Mixed | D12: C | E12: Low (Cut-Off) over Central Europe | F12: Tief Mitteleuropa
A13: 12 | B13: Na | C13: Meridional | D13: A | E13: Anticyclonic Northerly | F13: Nordlage, Mitteleuropa überwiegend antizyklonal
... A31: 30 | B31: Ü | C31: Undefined | D31: M | E31: Transistion / Undefined | F31: Übergangslage / Unbestimmt
E33: Colors according to DWD Standard coloring code
